Workbook

Sheet Sheet1
A6: 0 | B6: Zero | D6: 0 | E6: Zero
A7: =ROUND(A6+0.01,2) -> 0.01 | B7: Zero One | D7: 1 | E7: One
A8: =ROUND(A7+0.01,2) -> 0.02 | B8: Zero Two | D8: =D7+1 -> 2 | E8: Two
A9: =ROUND(A8+0.01,2) -> 0.03 | B9: Zero Three | D9: =D8+1 -> 3 | E9: Three
A10: =ROUND(A9+0.01,2) -> 0.04 | B10: Zero Four | D10: =D9+1 -> 4 | E10: Four
A11: =ROUND(A10+0.01,2) -> 0.05 | B11: Zero Five | D11: =D10+1 -> 5 | E11: Five
A12: =ROUND(A11+0.01,2) -> 0.06 | B12: Zero Six | D12: =D11+1 -> 6 | E12: Six
A13: =ROUND(A12+0.01,2) -> 0.07 | B13: Zero Seven | D13: =D12+1 -> 7 | E13: Seven
A14: =ROUND(A13+0.01,2) -> 0.08 | B14: Zero Eight | D14: =D13+1 -> 8 | E14: Eight
A15: =ROUND(A14+0.01,2) -> 0.09 | B15: Zero Nine | D15: =D14+1 -> 9 | E15: Nine
A16: =ROUND(A15+0.01,2) -> 0.1 | B16: One Zero | D16: =D15+1 -> 10 | E16: Ten
A17: =ROUND(A16+0.01,2) -> 0.11 | B17: One One | D17: =D16+1 -> 11 | E17: Eleven
A18: =ROUND(A17+0.01,2) -> 0.12 | B18: One Two | D18: =D17+1 -> 12 | E18: Twelve
A19: =ROUND(A18+0.01,2) -> 0.13 | B19: One Three | D19: =D18+1 -> 13 | E19: Thirteen
... A47: =ROUND(A46+0.01,2) -> 0.41 | B47: Four One | D47: =D46+1 -> 41 | E47: Fourty One
D48: =D47+1 -> 42 | E48: Fourty Two
A49: =ROUND(A47+0.01,2) -> 0.42 | B49: Four Two
A50: =ROUND(A49+0.01,2) -> 0.43 | B50: Four Three | D50: =D48+1 -> 43 | E50: Fourty Three
A51: =ROUND(A50+0.01,2) -> 0.44 | B51: Four Four | D51: =D50+1 -> 44 | E51: Fourty Four
A52: =ROUND(A51+0.01,2) -> 0.45 | B52: Four Five | D52: =D51+1 -> 45 | E52: Fourty Five
A53: =ROUND(A52+0.01,2) -> 0.46 | B53: Four Six | D53: =D52+1 -> 46 | E53: Fourty Six
A54: =ROUND(A53+0.01,2) -> 0.47 | B54: Four Seven | D54: =D53+1 -> 47 | E54: Fourty Seven
A55: =ROUND(A54+0.01,2) -> 0.48 | B55: Four Eight | D55: =D54+1 -> 48 | E55: Fourty Eight
A56: =ROUND(A55+0.01,2) -> 0.49 | B56: Four Nine | D56: =D55+1 -> 49 | E56: Fourty Nine
A57: =ROUND(A56+0.01,2) -> 0.5 | B57: Five Zero | D57: =D56+1 -> 50 | E57: Fifty
A58: =ROUND(A57+0.01,2) -> 0.51 | B58: Five One | D58: =D57+1 -> 51 | E58: Fifty One
A59: =ROUND(A58+0.01,2) -> 0.52 | B59: Five Two | D59: =D58+1 -> 52 | E59: Fifty Two
A60: =ROUND(A59+0.01,2) -> 0.53 | B60: Five Three | D60: =D59+1 -> 53 | E60: Fifty Three
A61: =ROUND(A60+0.01,2) -> 0.54 | B61: Five Four | D61: =D60+1 -> 54 | E61: Fifty Four
A62: =ROUND(A61+0.01,2) -> 0.55 | B62: Five Five | D62: =D61+1 -> 55 | E62: Fifty Five
... A106: =ROUND(A105+0.01,2) -> 0.99 | B106: Nine Nine | D106: =D105+1 -> 99 | E106: Ninty Nine
D107: =D106+1 -> 100 | E107: One Hundred
D108: =D107+1 -> 101 | E108: One Hundred & One
D109: =D108+1 -> 102 | E109: One Hundred & Two
D110: =D109+1 -> 103 | E110: One Hundred & Three
D111: =D110+1 -> 104 | E111: One Hundred & Four
D112: =D111+1 -> 105 | E112: One Hundred & Five
D113: =D112+1 -> 106 | E113: One Hundred & Six
D114: =D113+1 -> 107 | E114: One Hundred & Seven
D115: =D114+1 -> 108 | E115: One Hundred & Eight
...

Sheet نواتج التعلم
A1: العام والفصل الدراسي: | C1: الفصل الأول 1446 ه
A2: رمز المقرر واسمه: | C2: 5116 قصد المحاسبة المالية
A3: رقم الشعبة:
A4: اسم عضو هيئة التدريس:
A6: المجال | B6: الرمز | C6: نواتج التعلم | D6: المستوى المستهدف | F6: المستوى الفعلي | H6: إحصائيات
D7: الطلبة المستهدف تحقيقهم للدرجة | E7: الدرجة المستهدف تحقيقها | F7: الطلبة الذين حققوا الدرجة المطلوبة | G7: هل تحقق المستهدف؟ | H7: عناصر التقييم | I7: مجموع الدرجات | J7: عدد الطلبة
H8: =SUM(H10:H22) -> 16 | I8: =SUM(I10:I22) -> 0 | J8: =COUNTA(جدول_الرصد[الاسم]) -> 23
B9: الرمز | C9: نواتج التعلم | D9: المستوى المستهدف 1 | E9: المستوى المستهدف 2 | F9: المستوى الفعلي | G9: عمود1 | H9: عدد الأسئلة | I9: مجموع الدرجات
A10: المعرفة | B10: 1.1 | C10: معرفة المحاسبة ومجالاتها ودروها الاقتصادي | D10: 0.7 | E10: 0.75 | F10: ='قياس النواتج'!$D$14 -> 1 | G10: =IF(OR(D10="",E10="",F10=""),"",IF(F10>=D10,"نعم","لا")) -> نعم | H10: ='قياس النواتج'!$D$3 -> 1 | I10: ='قياس النواتج'!$D$19 -> 0
A11: =A10 -> المعرفة | B11: 1.2 | C11: معرفة كيف يتم العمل المحاسبي في كل من المحاسبة المالية والحكومية والوطنية ومحاسة التكاليف | D11: 0.7 | E11: 0.75 | F11: ='قياس النواتج'!$E$14 -> 1 | G11: =IF(OR(D11="",E11="",F11=""),"",IF(F11>=D11,"نعم","لا")) -> نعم | H11: ='قياس النواتج'!$E$3 -> 5 | I11: ='قياس النواتج'!$E$19 -> 0
A12: =A11 -> المعرفة | B12: 1.3 | C12: معرفة كيفية إعداد القوائم المالية وقراءتها وتحليلها واستخلاص المعلومات منها | D12: 0.7 | E12: 0.75 | F12: ='قياس النواتج'!$F$14 -> 1 | G12: =IF(OR(D12="",E12="",F12=""),"",IF(F12>=D12,"نعم","لا")) -> نعم | H12: ='قياس النواتج'!$F$3 -> 3 | I12: ='قياس النواتج'!$F$19 -> 0
A13: =A12 -> المعرفة | B13: 1.4 | F13: ='قياس النواتج'!$G$14 | G13: =IF(OR(D13="",E13="",F13=""),"",IF(F13>=D13,"نعم","لا")) | H13: ='قياس النواتج'!$G$3 | I13: ='قياس النواتج'!$G$19
A14: =A13 -> المعرفة | B14: 1.5 | F14: ='قياس النواتج'!$H$14 | G14: =IF(OR(D14="",E14="",F14=""),"",IF(F14>=D14,"نعم","لا")) | H14: ='قياس النواتج'!$H$3 | I14: ='قياس النواتج'!$H$19
A15: المهارات | B15: 2.1 | C15: القدرة على العمل في المجال المحاسبي | D15: 0.7 | E15: 0.75 | F15: ='قياس النواتج'!$I$14 -> 1 | G15: =IF(OR(D15="",E15="",F15=""),"",IF(F15>=D15,"نعم","لا")) -> نعم | H15: ='قياس النواتج'!$I$3 -> 1 | I15: ='قياس النواتج'!$I$19 -> 0
A16: =A15 -> المهارات | B16: 2.2 | C16: القدرة على تحليل وقراءة القوائم المالية | D16: 0.7 | E16: 0.75 | F16: ='قياس النواتج'!$J$14 -> 1 | G16: =IF(OR(D16="",E16="",F16=""),"",IF(F16>=D16,"نعم","لا")) -> نعم | H16: ='قياس النواتج'!$J$3 -> 3 | I16: ='قياس النواتج'!$J$19 -> 0
A17: =A16 -> المهارات | B17: 2.3 | C17: الربط بين المحاسبة والاقتصاد | D17: 0.7 | E17: 0.75 | F17: ='قياس النواتج'!$K$14 -> 1 | G17: =IF(OR(D17="",E17="",F17=""),"",IF(F17>=D17,"نعم","لا")) -> نعم | H17: ='قياس النواتج'!$K$3 -> 3 | I17: ='قياس النواتج'!$K$19 -> 0
A18: =A17 -> المهارات | B18: 2.4 | F18: ='قياس النواتج'!$L$14 | G18: =IF(OR(D18="",E18="",F18=""),"",IF(F18>=D18,"نعم","لا")) | H18: ='قياس النواتج'!$L$3 | I18: ='قياس النواتج'!$L$19
A19: =A18 -> المهارات | B19: 2.5 | F19: ='قياس النواتج'!$M$14 | G19: =IF(OR(D19="",E19="",F19=""),"",IF(F19>=D19,"نعم","لا")) | H19: ='قياس النواتج'!$M$3 | I19: ='قياس النواتج'!$M$19
A20: القيم | B20: 3.1 | C20: المشاركة مع الطلاب في المناقشات والواجبات الجماعية | D20: 0.7 | E20: 0.75 | F20: ='قياس النواتج'!$N$14 | G20: =IF(OR(D20="",E20="",F20=""),"",IF(F20>=D20,"نعم","لا")) | H20: ='قياس النواتج'!$N$3 -> 0 | I20: ='قياس النواتج'!$N$19 -> 0
A21: =A20 -> القيم | B21: 3.2 | C21: أن يعتمد الطالب على الذات في تحصيل العلم والقيام بالواجبات الفردية المطلوبة | D21: 0.7 | E21: 0.75 | F21: ='قياس النواتج'!$O$14 | G21: =IF(OR(D21="",E21="",F21=""),"",IF(F21>=D21,"نعم","لا")) | H21: ='قياس النواتج'!$O$3 -> 0 | I21: ='قياس النواتج'!$O$19 -> 0
A22: =A21 -> القيم | B22: 3.3 | C22: المشاركة مع الطلاب في المناقشات والواجبات الجماعية | D22: 0.7 | E22: 0.75 | F22: ='قياس النواتج'!$P$14 | G22: =IF(OR(D22="",E22="",F22=""),"",IF(F22>=D22,"نعم","لا")) | H22: ='قياس النواتج'!$P$3 -> 0 | I22: ='قياس النواتج'!$P$19 -> 0

Sheet رصد الدرجات
D1: عنصر التقييم | E1: اختبار فصلي 1 | I1: اختبار فصلي 2 | M1: الواجبات | Q1: الاختبار النهائي
D2: رقم السؤال | E2: س1 | F2: س2 | G2: س3 | H2: س4 | I2: س1 | J2: س2 | K2: س3 | L2: س4 | M2: س1 | N2: س2 | O2: س3 | P2: س4 | Q2: س1 | R2: س2 | S2: س3 | T2: س4
D3: رمز الناتج | E3: 1.1 | F3: 1.2 | G3: 2.2 | H3: 2.3 | I3: 1.2 | J3: 1.3 | K3: 2.1 | L3: 1.3 | M3: 1.2 | N3: 1.3 | O3: 2.2 | P3: 2.3 | Q3: 1.2 | R3: 2.2 | S3: 1.2 | T3: 2.3 | AI3: مجموع الدرجات
D4: درجة السؤال | AI4: =SUM(E4:AH4) -> 0
D5: ناتج التعلم | E5: =IFERROR(IF(VLOOKUP(E3,نواتج_التعلم[],2,FALSE)=0,"المخرج لم يحدد في جدول نواتج التعلم",VLOOKUP(E3,نواتج_التعلم[],2,FALSE)),"") -> معرفة المحاسبة ومجالاتها ودروها الاقتصادي | F5: =IFERROR(IF(VLOOKUP(F3,نواتج_التعلم[],2,FALSE)=0,"المخرج لم يحدد في جدول نواتج التعلم",VLOOKUP(F3,نواتج_التعلم[],2,FALSE)),"") -> معرفة كيف يتم العمل المحاسبي في كل من المحاسبة المالية والحكومية والوطنية ومحاسة التكاليف | G5: =IFERROR(IF(VLOOKUP(G3,نواتج_التعلم[],2,FALSE)=0,"المخرج لم يحدد في جدول نواتج التعلم",VLOOKUP(G3,نواتج_التعلم[],2,FALSE)),"") -> القدرة على تحليل وقراءة القوائم المالية | H5: =IFERROR(IF(VLOOKUP(H3,نواتج_التعلم[],2,FALSE)=0,"المخرج لم يحدد في جدول نواتج التعلم",VLOOKUP(H3,نواتج_التعلم[],2,FALSE)),"") -> الربط بين المحاسبة والاقتصاد | I5: =IFERROR(IF(VLOOKUP(I3,نواتج_التعلم[],2,FALSE)=0,"المخرج لم يحدد في جدول نواتج التعلم",VLOOKUP(I3,نواتج_التعلم[],2,FALSE)),"") -> معرفة كيف يتم العمل المحاسبي في كل من المحاسبة المالية والحكومية والوطنية ومحاسة التكاليف | J5: =IFERROR(IF(VLOOKUP(J3,نواتج_التعلم[],2,FALSE)=0,"المخرج لم يحدد في جدول نواتج التعلم",VLOOKUP(J3,نواتج_التعلم[],2,FALSE)),"") -> معرفة كيفية إعداد القوائم المالية وقراءتها وتحليلها واستخلاص المعلومات منها | K5: =IFERROR(IF(VLOOKUP(K3,نواتج_التعلم[],2,FALSE)=0,"المخرج لم يحدد في جدول نواتج التعلم",VLOOKUP(K3,نواتج_التعلم[],2,FALSE)),"") -> القدرة على العمل في المجال المحاسبي | L5: =IFERROR(IF(VLOOKUP(L3,نواتج_التعلم[],2,FALSE)=0,"المخرج لم يحدد في جدول نواتج التعلم",VLOOKUP(L3,نواتج_التعلم[],2,FALSE)),"") -> معرفة كيفية إعداد القوائم المالية وقراءتها وتحليلها واستخلاص المعلومات منها | ... AH5: =IFERROR(IF(VLOOKUP(AH3,نواتج_التعلم[],2,FALSE)=0,"المخرج لم يحدد في جدول نواتج التعلم",VLOOKUP(AH3,نواتج_التعلم[],2,FALSE)),"")
A6: عدد | B6: الرقم الجامعي | C6: ="الاسم"&" ("&COUNTA(جدول_الرصد[الاسم])&")" -> الاسم (23) | D6: مجموع الدرجات | E6: =IF(E4=0,"",E4) | F6: =IF(F4=0,"",F4) | G6: =IF(G4=0,"",G4) | H6: =IF(H4=0,"",H4) | I6: =IF(I4=0,"",I4) | J6: =IF(J4=0,"",J4) | K6: =IF(K4=0,"",K4) | L6: =IF(L4=0,"",L4) | ... AH6: =IF(AH4=0,"",AH4)
A7: عدد | B7: الرقم الجامعي | C7: الاسم | D7: المجموع | E7: 1 | F7: 2 | G7: 3 | H7: 4 | I7: 5 | J7: 6 | K7: 7 | L7: 8 | M7: 9 | N7: 10 | O7: 11 | P7: 12 | Q7: 13 | R7: 14 | S7: 15 | T7: 16 | U7: 17 | V7: 18 | W7: 19 | X7: 20 | Y7: 21 | Z7: 22 | AA7: 23 | AB7: 24 | AC7: 25 | AD7: 26 | AE7: 27 | AF7: 28 | AG7: 29 | AH7: 30
A8: =ROW()-7 -> 1 | C8: عزيز أنصاري | D8: =IF(C8="","",SUM(E8:AH8)) -> 88 | E8: 2 | F8: 2 | G8: 2 | H8: 2 | I8: 2 | J8: 2 | K8: 2 | L8: 2 | M8: 5 | N8: 5 | O8: 5 | P8: 5 | Q8: 20 | R8: 16 | S8: 10 | T8: 6
A9: =ROW()-7 -> 2 | C9: أكبر علمشاح | D9: =IF(C9="","",SUM(E9:AH9)) -> 92 | E9: 2 | F9: 2 | G9: 1 | H9: 4 | I9: 3 | J9: 2 | K9: 2 | L9: 2 | M9: 5 | N9: 5 | O9: 5 | P9: 5 | Q9: 15 | R9: 14 | S9: 15 | T9: 10
A10: =ROW()-7 -> 3 | C10: محمد فائز الرشيد | D10: =IF(C10="","",SUM(E10:AH10)) -> 85 | E10: 3 | F10: 2 | G10: 2 | H10: 2 | I10: 2 | J10: 1 | K10: 2 | L10: 4 | M10: 5 | N10: 5 | O10: 5 | P10: 5 | Q10: 10 | R10: 16 | S10: 18 | T10: 3
A11: =ROW()-7 -> 4 | C11: محمد فتحون مذكر | D11: =IF(C11="","",SUM(E11:AH11)) -> 93 | E11: 3 | F11: 3 | G11: 3 | H11: 1 | I11: 2 | J11: 3 | K11: 2 | L11: 2 | M11: 5 | N11: 5 | O11: 5 | P11: 5 | Q11: 16 | R11: 16 | S11: 15 | T11: 7
A12: =ROW()-7 -> 5 | C12: إبراهيم باه | D12: =IF(C12="","",SUM(E12:AH12)) -> 96 | E12: 2 | F12: 3 | G12: 3 | H12: 2 | I12: 2 | J12: 2 | K12: 3 | L12: 2 | M12: 5 | N12: 5 | O12: 5 | P12: 5 | Q12: 20 | R12: 16 | S12: 14 | T12: 7
A13: =ROW()-7 -> 6 | C13: عبداللطيف محمد أمين | D13: =IF(C13="","",SUM(E13:AH13)) -> 97 | E13: 1.5 | F13: 3 | G13: 2 | H13: 3 | I13: 2.5 | J13: 2 | K13: 2 | L13: 3 | M13: 5 | N13: 5 | O13: 5 | P13: 5 | Q13: 20 | R13: 16 | S13: 14 | T13: 8
A14: =ROW()-7 -> 7 | C14: خالد الحربي | D14: =IF(C14="","",SUM(E14:AH14)) -> 97 | E14: 2 | F14: 2.5 | G14: 3 | H14: 2 | I14: 2.5 | J14: 2 | K14: 2 | L14: 3 | M14: 5 | N14: 5 | O14: 5 | P14: 5 | Q14: 20 | R14: 16 | S14: 14 | T14: 8
A15: =ROW()-7 -> 8 | C15: عبد الحكيم عبد الرحمن | D15: =IF(C15="","",SUM(E15:AH15)) -> 98 | E15: 2.5 | F15: 2.5 | G15: 2.5 | H15: 2.5 | I15: 2 | J15: 3 | K15: 2 | L15: 3 | M15: 5 | N15: 5 | O15: 5 | P15: 5 | Q15: 20 | R15: 16 | S15: 14 | T15: 8
A16: =ROW()-7 -> 9 | C16: محمد محبوب حسين | D16: =IF(C16="","",SUM(E16:AH16)) -> 91 | E16: 3 | F16: 2 | G16: 3 | H16: 2 | I16: 2 | J16: 2 | K16: 2 | L16: 3 | M16: 5 | N16: 5 | O16: 5 | P16: 5 | Q16: 15 | R16: 16 | S16: 14 | T16: 7
A17: =ROW()-7 -> 10 | C17: محمد ريزا الغفاري | D17: =IF(C17="","",SUM(E17:AH17)) -> 83 | E17: 2.5 | F17: 3 | G17: 2 | H17: 2 | I17: 2 | J17: 1.5 | K17: 3 | L17: 3 | M17: 5 | N17: 5 | O17: 5 | P17: 5 | Q17: 10 | R17: 16 | S17: 14 | T17: 4
A18: =ROW()-7 -> 11 | C18: سليمان حنيف | D18: =IF(C18="","",SUM(E18:AH18)) -> 98 | E18: 2 | F18: 3 | G18: 2 | H18: 3 | I18: 3 | J18: 3 | K18: 2 | L18: 2 | M18: 5 | N18: 5 | O18: 5 | P18: 5 | Q18: 20 | R18: 16 | S18: 14 | T18: 8
A19: =ROW()-7 -> 12 | C19: النفيدي محمد عثمان | D19: =IF(C19="","",SUM(E19:AH19)) -> 80 | E19: 2 | F19: 2 | G19: 2 | H19: 2 | I19: 3 | J19: 1 | K19: 2 | L19: 2 | M19: 5 | N19: 5 | O19: 5 | P19: 5 | Q19: 15 | R19: 10 | S19: 10 | T19: 9
A20: =ROW()-7 -> 13 | C20: زبير عبدالسميع | D20: =IF(C20="","",SUM(E20:AH20)) -> 0
A21: =ROW()-7 -> 14 | C21: سهيل محمد مجددي | D21: =IF(C21="","",SUM(E21:AH21)) -> 0
A22: =ROW()-7 -> 15 | C22: أحمد رادباده | D22: =IF(C22="","",SUM(E22:AH22)) -> 0
A23: =ROW()-7 -> 16 | C23: محمد شفان | D23: =IF(C23="","",SUM(E23:AH23)) -> 0
A24: =ROW()-7 -> 17 | C24: سالم الهاجري | D24: =IF(C24="","",SUM(E24:AH24)) -> 0
A25: =ROW()-7 -> 18 | C25: سلمان المطيري | D25: =IF(C25="","",SUM(E25:AH25)) -> 0
A26: =ROW()-7 -> 19 | C26: علي الشنقيطي | D26: =IF(C26="","",SUM(E26:AH26)) -> 0
A27: =ROW()-7 -> 20 | C27: مسعود الرحمن | D27: =IF(C27="","",SUM(E27:AH27)) -> 0
A28: =ROW()-7 -> 21 | C28: مدثر محمد | D28: =IF(C28="","",SUM(E28:AH28)) -> 0
A29: =ROW()-7 -> 22 | C29: أبوبكر الماحي | D29: =IF(C29="","",SUM(E29:AH29)) -> 0
A30: =ROW()-7 -> 23 | C30: أبوكر عبدالمجيد | D30: =IF(C30="","",SUM(E30:AH30)) -> 0
A31: =ROW()-7 -> 24 | D31: =IF(C31="","",SUM(E31:AH31))
A32: =ROW()-7 -> 25 | D32: =IF(C32="","",SUM(E32:AH32))
A33: =ROW()-7 -> 26 | D33: =IF(C33="","",SUM(E33:AH33))
A34: =ROW()-7 -> 27 | D34: =IF(C34="","",SUM(E34:AH34))
A35: =ROW()-7 -> 28 | D35: =IF(C35="","",SUM(E35:AH35))
A36: =ROW()-7 -> 29 | D36: =IF(C36="","",SUM(E36:AH36))
A37: =ROW()-7 -> 30 | D37: =IF(C37="","",SUM(E37:AH37))
A38: =ROW()-7 -> 31 | D38: =IF(C38="","",SUM(E38:AH38))
A39: =ROW()-7 -> 32 | D39: =IF(C39="","",SUM(E39:AH39))
A40: =ROW()-7 -> 33 | D40: =IF(C40="","",SUM(E40:AH40))
...

Sheet قياس النواتج
A1: نواتج التعلم | B1: رمز ناتج التعلم | D1: 1.1 | E1: 1.2 | F1: 1.3 | G1: 1.4 | H1: 1.5 | I1: 2.1 | J1: 2.2 | K1: 2.3 | L1: 2.4 | M1: 2.5 | N1: 3.1 | O1: 3.2 | P1: 3.3 | W1: تاريخ النسخة | X1: 45333
B2: ناتج التعلم | D2: =IFERROR(IF('نواتج التعلم'!C10=0,"",'نواتج التعلم'!C10),"") -> معرفة المحاسبة ومجالاتها ودروها الاقتصادي | E2: =IFERROR(IF('نواتج التعلم'!C11=0,"",'نواتج التعلم'!C11),"") -> معرفة كيف يتم العمل المحاسبي في كل من المحاسبة المالية والحكومية والوطنية ومحاسة التكاليف | F2: =IFERROR(IF('نواتج التعلم'!C12=0,"",'نواتج التعلم'!C12),"") -> معرفة كيفية إعداد القوائم المالية وقراءتها وتحليلها واستخلاص المعلومات منها | G2: =IFERROR(IF('نواتج التعلم'!C13=0,"",'نواتج التعلم'!C13),"") | H2: =IFERROR(IF('نواتج التعلم'!C14=0,"",'نواتج التعلم'!C14),"") | I2: =IFERROR(IF('نواتج التعلم'!C15=0,"",'نواتج التعلم'!C15),"") -> القدرة على العمل في المجال المحاسبي | J2: =IFERROR(IF('نواتج التعلم'!C16=0,"",'نواتج التعلم'!C16),"") -> القدرة على تحليل وقراءة القوائم المالية | K2: =IFERROR(IF('نواتج التعلم'!C17=0,"",'نواتج التعلم'!C17),"") -> الربط بين المحاسبة والاقتصاد | L2: =IFERROR(IF('نواتج التعلم'!C18=0,"",'نواتج التعلم'!C18),"") | M2: =IFERROR(IF('نواتج التعلم'!C19=0,"",'نواتج التعلم'!C19),"") | N2: =IFERROR(IF('نواتج التعلم'!C20=0,"",'نواتج التعلم'!C20),"") -> المشاركة مع الطلاب في المناقشات والواجبات الجماعية | O2: =IFERROR(IF('نواتج التعلم'!C21=0,"",'نواتج التعلم'!C21),"") -> أن يعتمد الطالب على الذات في تحصيل العلم والقيام بالواجبات الفردية المطلوبة | P2: =IFERROR(IF('نواتج التعلم'!C22=0,"",'نواتج التعلم'!C22),"") -> المشاركة مع الطلاب في المناقشات والواجبات الجماعية
B3: عدد عناصر التقييم المرتبطة | D3: =IF(D2="","",COUNTIF('رصد الدرجات'!$3:$3,D1)) -> 1 | E3: =IF(E2="","",COUNTIF('رصد الدرجات'!$3:$3,E1)) -> 5 | F3: =IF(F2="","",COUNTIF('رصد الدرجات'!$3:$3,F1)) -> 3 | G3: =IF(G2="","",COUNTIF('رصد الدرجات'!$3:$3,G1)) | H3: =IF(H2="","",COUNTIF('رصد الدرجات'!$3:$3,H1)) | I3: =IF(I2="","",COUNTIF('رصد الدرجات'!$3:$3,I1)) -> 1 | J3: =IF(J2="","",COUNTIF('رصد الدرجات'!$3:$3,J1)) -> 3 | K3: =IF(K2="","",COUNTIF('رصد الدرجات'!$3:$3,K1)) -> 3 | ... P3: =IF(P2="","",COUNTIF('رصد الدرجات'!$3:$3,P1)) -> 0
B4: الدرجة المقدرة لكل ناتج | D4: =IF(D2="","",SUMIF('رصد الدرجات'!$3:$3,D$1,'رصد الدرجات'!$4:$4)) -> 0 | E4: =IF(E2="","",SUMIF('رصد الدرجات'!$3:$3,E$1,'رصد الدرجات'!$4:$4)) -> 0 | F4: =IF(F2="","",SUMIF('رصد الدرجات'!$3:$3,F$1,'رصد الدرجات'!$4:$4)) -> 0 | G4: =IF(G2="","",SUMIF('رصد الدرجات'!$3:$3,G$1,'رصد الدرجات'!$4:$4)) | H4: =IF(H2="","",SUMIF('رصد الدرجات'!$3:$3,H$1,'رصد الدرجات'!$4:$4)) | I4: =IF(I2="","",SUMIF('رصد الدرجات'!$3:$3,I$1,'رصد الدرجات'!$4:$4)) -> 0 | J4: =IF(J2="","",SUMIF('رصد الدرجات'!$3:$3,J$1,'رصد الدرجات'!$4:$4)) -> 0 | K4: =IF(K2="","",SUMIF('رصد الدرجات'!$3:$3,K$1,'رصد الدرجات'!$4:$4)) -> 0 | ... P4: =IF(P2="","",SUMIF('رصد الدرجات'!$3:$3,P$1,'رصد الدرجات'!$4:$4)) -> 0
A6: مؤشر الدرجة | B6: الدرجة المستهدف تحقيقها | D6: =IF(D2="","",VLOOKUP(D1,نواتج_التعلم[],4,FALSE)) -> 0.75 | E6: =IF(E2="","",VLOOKUP(E1,نواتج_التعلم[],4,FALSE)) -> 0.75 | F6: =IF(F2="","",VLOOKUP(F1,نواتج_التعلم[],4,FALSE)) -> 0.75 | G6: =IF(G2="","",VLOOKUP(G1,نواتج_التعلم[],4,FALSE)) | H6: =IF(H2="","",VLOOKUP(H1,نواتج_التعلم[],4,FALSE)) | I6: =IF(I2="","",VLOOKUP(I1,نواتج_التعلم[],4,FALSE)) -> 0.75 | J6: =IF(J2="","",VLOOKUP(J1,نواتج_التعلم[],4,FALSE)) -> 0.75 | K6: =IF(K2="","",VLOOKUP(K1,نواتج_التعلم[],4,FALSE)) -> 0.75 | ... P6: =IF(P2="","",VLOOKUP(P1,نواتج_التعلم[],4,FALSE)) -> 0.75
D7: =IF(OR(D2="",D3=0),"",D19*D6) -> 0 | E7: =IF(OR(E2="",E3=0),"",E19*E6) -> 0 | F7: =IF(OR(F2="",F3=0),"",F19*F6) -> 0 | G7: =IF(OR(G2="",G3=0),"",G19*G6) | H7: =IF(OR(H2="",H3=0),"",H19*H6) | I7: =IF(OR(I2="",I3=0),"",I19*I6) -> 0 | J7: =IF(OR(J2="",J3=0),"",J19*J6) -> 0 | K7: =IF(OR(K2="",K3=0),"",K19*K6) -> 0 | ... P7: =IF(OR(P2="",P3=0),"",P19*P6)
B8: متوسط درجات الطلبة | D8: =IFERROR(IF(OR(D2="",D3=0),"",SUM(قياس_النواتج[1.1])/COUNTA('رصد الدرجات'!$C$8:$C$47)),"") -> 1.1956522 | E8: =IFERROR(IF(OR(E2="",E3=0),"",SUM(قياس_النواتج[1.2])/COUNTA('رصد الدرجات'!$C$8:$C$47)),"") -> 21.086957 | F8: =IFERROR(IF(OR(F2="",F3=0),"",SUM(قياس_النواتج[1.3])/COUNTA('رصد الدرجات'!$C$8:$C$47)),"") -> 5.0217391 | G8: =IFERROR(IF(OR(G2="",G3=0),"",SUM(قياس_النواتج[1.4])/COUNTA('رصد الدرجات'!$C$8:$C$47)),"") | H8: =IFERROR(IF(OR(H2="",H3=0),"",SUM(قياس_النواتج[1.5])/COUNTA('رصد الدرجات'!$C$8:$C$47)),"") | I8: =IFERROR(IF(OR(I2="",I3=0),"",SUM(قياس_النواتج[2.1])/COUNTA('رصد الدرجات'!$C$8:$C$47)),"") -> 1.1304348 | J8: =IFERROR(IF(OR(J2="",J3=0),"",SUM(قياس_النواتج[2.2])/COUNTA('رصد الدرجات'!$C$8:$C$47)),"") -> 11.804348 | K8: =IFERROR(IF(OR(K2="",K3=0),"",SUM(قياس_النواتج[2.3])/COUNTA('رصد الدرجات'!$C$8:$C$47)),"") -> 7.5 | L8: =IFERROR(IF(OR(L2="",L3=0),"",SUM(قياس_النواتج[2.4])/COUNTA('رصد الدرجات'!$C$8:$C$47)),"") | M8: =IFERROR(IF(OR(M2="",M3=0),"",SUM(قياس_النواتج[2.5])/COUNTA('رصد الدرجات'!$C$8:$C$47)),"") | N8: =IFERROR(IF(OR(N2="",N3=0),"",SUM(قياس_النواتج[3.1])/COUNTA('رصد الدرجات'!$C$8:$C$47)),"") | O8: =IFERROR(IF(OR(O2="",O3=0),"",SUM(قياس_النواتج[3.2])/COUNTA('رصد الدرجات'!$C$8:$C$47)),"") | P8: =IFERROR(IF(OR(P2="",P3=0),"",SUM(قياس_النواتج[3.3])/COUNTA('رصد الدرجات'!$C$8:$C$47)),"")
D9: =IFERROR(IF(OR(D2="",D3=0),"",D8/D19),"") | E9: =IFERROR(IF(OR(E2="",E3=0),"",E8/E19),"") | F9: =IFERROR(IF(OR(F2="",F3=0),"",F8/F19),"") | G9: =IFERROR(IF(OR(G2="",G3=0),"",G8/G19),"") | H9: =IFERROR(IF(OR(H2="",H3=0),"",H8/H19),"") | I9: =IFERROR(IF(OR(I2="",I3=0),"",I8/I19),"") | J9: =IFERROR(IF(OR(J2="",J3=0),"",J8/J19),"") | K9: =IFERROR(IF(OR(K2="",K3=0),"",K8/K19),"") | ... P9: =IFERROR(IF(OR(P2="",P3=0),"",P8/P19),"")
A11: مؤشر الطلبة | B11: الطلبة المستهدف تحقيقهم للدرجة | D11: =IF(D2="","",VLOOKUP(D1,نواتج_التعلم[],3,FALSE)) -> 0.7 | E11: =IF(E2="","",VLOOKUP(E1,نواتج_التعلم[],3,FALSE)) -> 0.7 | F11: =IF(F2="","",VLOOKUP(F1,نواتج_التعلم[],3,FALSE)) -> 0.7 | G11: =IF(G2="","",VLOOKUP(G1,نواتج_التعلم[],3,FALSE)) | H11: =IF(H2="","",VLOOKUP(H1,نواتج_التعلم[],3,FALSE)) | I11: =IF(I2="","",VLOOKUP(I1,نواتج_التعلم[],3,FALSE)) -> 0.7 | J11: =IF(J2="","",VLOOKUP(J1,نواتج_التعلم[],3,FALSE)) -> 0.7 | K11: =IF(K2="","",VLOOKUP(K1,نواتج_التعلم[],3,FALSE)) -> 0.7 | ... P11: =IF(P2="","",VLOOKUP(P1,نواتج_التعلم[],3,FALSE)) -> 0.7
D12: =IF(D2="","",SUM(D13,D15)*D11) -> 16.1 | E12: =IF(E2="","",SUM(E13,E15)*E11) -> 16.1 | F12: =IF(F2="","",SUM(F13,F15)*F11) -> 16.1 | G12: =IF(G2="","",SUM(G13,G15)*G11) | H12: =IF(H2="","",SUM(H13,H15)*H11) | I12: =IF(I2="","",SUM(I13,I15)*I11) -> 16.1 | J12: =IF(J2="","",SUM(J13,J15)*J11) -> 16.1 | K12: =IF(K2="","",SUM(K13,K15)*K11) -> 16.1 | ... P12: =IF(P2="","",SUM(P13,P15)*P11) -> 0
B13: الطلبة الذين حققوا المستهدف | D13: =IF(OR(D2="",D3=0),"",COUNTIF(قياس_النواتج[1.1],">="&D7)) -> 23 | E13: =IF(OR(E2="",E3=0),"",COUNTIF(قياس_النواتج[1.2],">="&E7)) -> 23 | F13: =IF(OR(F2="",F3=0),"",COUNTIF(قياس_النواتج[1.3],">="&F7)) -> 23 | G13: =IF(OR(G2="",G3=0),"",COUNTIF(قياس_النواتج[1.4],">="&G7)) | H13: =IF(OR(H2="",H3=0),"",COUNTIF(قياس_النواتج[1.5],">="&H7)) | I13: =IF(OR(I2="",I3=0),"",COUNTIF(قياس_النواتج[2.1],">="&I7)) -> 23 | J13: =IF(OR(J2="",J3=0),"",COUNTIF(قياس_النواتج[2.2],">="&J7)) -> 23 | K13: =IF(OR(K2="",K3=0),"",COUNTIF(قياس_النواتج[2.3],">="&K7)) -> 23 | L13: =IF(OR(L2="",L3=0),"",COUNTIF(قياس_النواتج[2.4],">="&L7)) | M13: =IF(OR(M2="",M3=0),"",COUNTIF(قياس_النواتج[2.5],">="&M7)) | N13: =IF(OR(N2="",N3=0),"",COUNTIF(قياس_النواتج[3.1],">="&N7)) | O13: =IF(OR(O2="",O3=0),"",COUNTIF(قياس_النواتج[3.2],">="&O7)) | P13: =IF(OR(P2="",P3=0),"",COUNTIF(قياس_النواتج[3.3],">="&P7))
D14: =IFERROR(IF(OR(D2="",D3=0),"",D13/(SUM(D13,D15))),"") -> 1 | E14: =IFERROR(IF(OR(E2="",E3=0),"",E13/(SUM(E13,E15))),"") -> 1 | F14: =IFERROR(IF(OR(F2="",F3=0),"",F13/(SUM(F13,F15))),"") -> 1 | G14: =IFERROR(IF(OR(G2="",G3=0),"",G13/(SUM(G13,G15))),"") | H14: =IFERROR(IF(OR(H2="",H3=0),"",H13/(SUM(H13,H15))),"") | I14: =IFERROR(IF(OR(I2="",I3=0),"",I13/(SUM(I13,I15))),"") -> 1 | J14: =IFERROR(IF(OR(J2="",J3=0),"",J13/(SUM(J13,J15))),"") -> 1 | K14: =IFERROR(IF(OR(K2="",K3=0),"",K13/(SUM(K13,K15))),"") -> 1 | ... P14: =IFERROR(IF(OR(P2="",P3=0),"",P13/(SUM(P13,P15))),"")
B15: الطلبة الذين لم يحققوا المستهدف | D15: =IF(OR(D2="",D3=0),"",COUNTIF(قياس_النواتج[1.1],"<"&D7)) -> 0 | E15: =IF(OR(E2="",E3=0),"",COUNTIF(قياس_النواتج[1.2],"<"&E7)) -> 0 | F15: =IF(OR(F2="",F3=0),"",COUNTIF(قياس_النواتج[1.3],"<"&F7)) -> 0 | G15: =IF(OR(G2="",G3=0),"",COUNTIF(قياس_النواتج[1.4],"<"&G7)) | H15: =IF(OR(H2="",H3=0),"",COUNTIF(قياس_النواتج[1.5],"<"&H7)) | I15: =IF(OR(I2="",I3=0),"",COUNTIF(قياس_النواتج[2.1],"<"&I7)) -> 0 | J15: =IF(OR(J2="",J3=0),"",COUNTIF(قياس_النواتج[2.2],"<"&J7)) -> 0 | K15: =IF(OR(K2="",K3=0),"",COUNTIF(قياس_النواتج[2.3],"<"&K7)) -> 0 | L15: =IF(OR(L2="",L3=0),"",COUNTIF(قياس_النواتج[2.4],"<"&L7)) | M15: =IF(OR(M2="",M3=0),"",COUNTIF(قياس_النواتج[2.5],"<"&M7)) | N15: =IF(OR(N2="",N3=0),"",COUNTIF(قياس_النواتج[3.1],"<"&N7)) | O15: =IF(OR(O2="",O3=0),"",COUNTIF(قياس_النواتج[3.2],"<"&O7)) | P15: =IF(OR(P2="",P3=0),"",COUNTIF(قياس_النواتج[3.3],"<"&P7))
D16: =IFERROR(IF(OR(D2="",D3=0),"",D15/(SUM(D13,D15))),"") -> 0 | E16: =IFERROR(IF(OR(E2="",E3=0),"",E15/(SUM(E13,E15))),"") -> 0 | F16: =IFERROR(IF(OR(F2="",F3=0),"",F15/(SUM(F13,F15))),"") -> 0 | G16: =IFERROR(IF(OR(G2="",G3=0),"",G15/(SUM(G13,G15))),"") | H16: =IFERROR(IF(OR(H2="",H3=0),"",H15/(SUM(H13,H15))),"") | I16: =IFERROR(IF(OR(I2="",I3=0),"",I15/(SUM(I13,I15))),"") -> 0 | J16: =IFERROR(IF(OR(J2="",J3=0),"",J15/(SUM(J13,J15))),"") -> 0 | K16: =IFERROR(IF(OR(K2="",K3=0),"",K15/(SUM(K13,K15))),"") -> 0 | ... P16: =IFERROR(IF(OR(P2="",P3=0),"",P15/(SUM(P13,P15))),"")
A18: عدد | B18: الرقم الجامعي | C18: ="الاسم"&" ("&COUNTA(جدول_الرصد[الاسم])&")" -> الاسم (23) | D18: 1.1 | E18: 1.2 | F18: 1.3 | G18: 1.4 | H18: 1.5 | I18: 2.1 | J18: 2.2 | K18: 2.3 | L18: 2.4 | M18: 2.5 | N18: 3.1 | O18: 3.2 | P18: 3.3 | Q18: مجموع الدرجات | R18: التقدير
D19: =IF(D2="","",SUMIF('رصد الدرجات'!$3:$3,D$1,'رصد الدرجات'!$4:$4)) -> 0 | E19: =IF(E2="","",SUMIF('رصد الدرجات'!$3:$3,E$1,'رصد الدرجات'!$4:$4)) -> 0 | F19: =IF(F2="","",SUMIF('رصد الدرجات'!$3:$3,F$1,'رصد الدرجات'!$4:$4)) -> 0 | G19: =IF(G2="","",SUMIF('رصد الدرجات'!$3:$3,G$1,'رصد الدرجات'!$4:$4)) | H19: =IF(H2="","",SUMIF('رصد الدرجات'!$3:$3,H$1,'رصد الدرجات'!$4:$4)) | I19: =IF(I2="","",SUMIF('رصد الدرجات'!$3:$3,I$1,'رصد الدرجات'!$4:$4)) -> 0 | J19: =IF(J2="","",SUMIF('رصد الدرجات'!$3:$3,J$1,'رصد الدرجات'!$4:$4)) -> 0 | K19: =IF(K2="","",SUMIF('رصد الدرجات'!$3:$3,K$1,'رصد الدرجات'!$4:$4)) -> 0 | ... P19: =IF(P2="","",SUMIF('رصد الدرجات'!$3:$3,P$1,'رصد الدرجات'!$4:$4)) -> 0 | Q19: =SUM(D19:P19) -> 0
A20: عدد | B20: الرقم الجامعي | C20: اسم الطالب | D20: 1.1 | E20: 1.2 | F20: 1.3 | G20: 1.4 | H20: 1.5 | I20: 2.1 | J20: 2.2 | K20: 2.3 | L20: 2.4 | M20: 2.5 | N20: 3.1 | O20: 3.2 | P20: 3.3 | Q20: المجموع | R20: التقدير
A21: ='رصد الدرجات'!A8 -> 1 | B21: =IF('رصد الدرجات'!B8="","",'رصد الدرجات'!B8) | C21: =IF('رصد الدرجات'!C8="","",'رصد الدرجات'!C8) -> عزيز أنصاري | D21: =IF(D$2="","",IF($C21="","",SUMIF('رصد الدرجات'!$3:$3,D$1,'رصد الدرجات'!8:8))) -> 2 | E21: =IF(E$2="","",IF($C21="","",SUMIF('رصد الدرجات'!$3:$3,E$1,'رصد الدرجات'!8:8))) -> 39 | F21: =IF(F$2="","",IF($C21="","",SUMIF('رصد الدرجات'!$3:$3,F$1,'رصد الدرجات'!8:8))) -> 9 | G21: =IF(G$2="","",IF($C21="","",SUMIF('رصد الدرجات'!$3:$3,G$1,'رصد الدرجات'!8:8))) | H21: =IF(H$2="","",IF($C21="","",SUMIF('رصد الدرجات'!$3:$3,H$1,'رصد الدرجات'!8:8))) | I21: =IF(I$2="","",IF($C21="","",SUMIF('رصد الدرجات'!$3:$3,I$1,'رصد الدرجات'!8:8))) -> 2 | J21: =IF(J$2="","",IF($C21="","",SUMIF('رصد الدرجات'!$3:$3,J$1,'رصد الدرجات'!8:8))) -> 23 | K21: =IF(K$2="","",IF($C21="","",SUMIF('رصد الدرجات'!$3:$3,K$1,'رصد الدرجات'!8:8))) -> 13 | ... P21: =IF(P$2="","",IF($C21="","",SUMIF('رصد الدرجات'!$3:$3,P$1,'رصد الدرجات'!8:8))) -> 0 | Q21: =IF($C21="","",SUM(D21:P21)) -> 88 | R21: =IF(C21="","",IF(Q21>100,"خطأ",IF(Q21>=95,"أ+",IF(Q21>=90,"أ",IF(Q21>=85,"ب+",IF(Q21>=80,"ب",IF(Q21>=75,"ج+",IF(Q21>=70,"ج",IF(Q21>=65,"د+",IF(Q21>=60,"د",IF(Q21>=0,"ه",""))))))))))) -> ب+
A22: ='رصد الدرجات'!A9 -> 2 | B22: =IF('رصد الدرجات'!B9="","",'رصد الدرجات'!B9) | C22: =IF('رصد الدرجات'!C9="","",'رصد الدرجات'!C9) -> أكبر علمشاح | D22: =IF(D$2="","",IF($C22="","",SUMIF('رصد الدرجات'!$3:$3,D$1,'رصد الدرجات'!9:9))) -> 2 | E22: =IF(E$2="","",IF($C22="","",SUMIF('رصد الدرجات'!$3:$3,E$1,'رصد الدرجات'!9:9))) -> 40 | F22: =IF(F$2="","",IF($C22="","",SUMIF('رصد الدرجات'!$3:$3,F$1,'رصد الدرجات'!9:9))) -> 9 | G22: =IF(G$2="","",IF($C22="","",SUMIF('رصد الدرجات'!$3:$3,G$1,'رصد الدرجات'!9:9))) | H22: =IF(H$2="","",IF($C22="","",SUMIF('رصد الدرجات'!$3:$3,H$1,'رصد الدرجات'!9:9))) | I22: =IF(I$2="","",IF($C22="","",SUMIF('رصد الدرجات'!$3:$3,I$1,'رصد الدرجات'!9:9))) -> 2 | J22: =IF(J$2="","",IF($C22="","",SUMIF('رصد الدرجات'!$3:$3,J$1,'رصد الدرجات'!9:9))) -> 20 | K22: =IF(K$2="","",IF($C22="","",SUMIF('رصد الدرجات'!$3:$3,K$1,'رصد الدرجات'!9:9))) -> 19 | ... P22: =IF(P$2="","",IF($C22="","",SUMIF('رصد الدرجات'!$3:$3,P$1,'رصد الدرجات'!9:9))) -> 0 | Q22: =IF($C22="","",SUM(D22:P22)) -> 92 | R22: =IF(C22="","",IF(Q22>100,"خطأ",IF(Q22>=95,"أ+",IF(Q22>=90,"أ",IF(Q22>=85,"ب+",IF(Q22>=80,"ب",IF(Q22>=75,"ج+",IF(Q22>=70,"ج",IF(Q22>=65,"د+",IF(Q22>=60,"د",IF(Q22>=0,"ه",""))))))))))) -> أ
A23: ='رصد الدرجات'!A10 -> 3 | B23: =IF('رصد الدرجات'!B10="","",'رصد الدرجات'!B10) | C23: =IF('رصد الدرجات'!C10="","",'رصد الدرجات'!C10) -> محمد فائز الرشيد | D23: =IF(D$2="","",IF($C23="","",SUMIF('رصد الدرجات'!$3:$3,D$1,'رصد الدرجات'!10:10))) -> 3 | E23: =IF(E$2="","",IF($C23="","",SUMIF('رصد الدرجات'!$3:$3,E$1,'رصد الدرجات'!10:10))) -> 37 | F23: =IF(F$2="","",IF($C23="","",SUMIF('رصد الدرجات'!$3:$3,F$1,'رصد الدرجات'!10:10))) -> 10 | G23: =IF(G$2="","",IF($C23="","",SUMIF('رصد الدرجات'!$3:$3,G$1,'رصد الدرجات'!10:10))) | H23: =IF(H$2="","",IF($C23="","",SUMIF('رصد الدرجات'!$3:$3,H$1,'رصد الدرجات'!10:10))) | I23: =IF(I$2="","",IF($C23="","",SUMIF('رصد الدرجات'!$3:$3,I$1,'رصد الدرجات'!10:10))) -> 2 | J23: =IF(J$2="","",IF($C23="","",SUMIF('رصد الدرجات'!$3:$3,J$1,'رصد الدرجات'!10:10))) -> 23 | K23: =IF(K$2="","",IF($C23="","",SUMIF('رصد الدرجات'!$3:$3,K$1,'رصد الدرجات'!10:10))) -> 10 | ... P23: =IF(P$2="","",IF($C23="","",SUMIF('رصد الدرجات'!$3:$3,P$1,'رصد الدرجات'!10:10))) -> 0 | Q23: =IF($C23="","",SUM(D23:P23)) -> 85 | R23: =IF(C23="","",IF(Q23>100,"خطأ",IF(Q23>=95,"أ+",IF(Q23>=90,"أ",IF(Q23>=85,"ب+",IF(Q23>=80,"ب",IF(Q23>=75,"ج+",IF(Q23>=70,"ج",IF(Q23>=65,"د+",IF(Q23>=60,"د",IF(Q23>=0,"ه",""))))))))))) -> ب+
A24: ='رصد الدرجات'!A11 -> 4 | B24: =IF('رصد الدرجات'!B11="","",'رصد الدرجات'!B11) | C24: =IF('رصد الدرجات'!C11="","",'رصد الدرجات'!C11) -> محمد فتحون مذكر | D24: =IF(D$2="","",IF($C24="","",SUMIF('رصد الدرجات'!$3:$3,D$1,'رصد الدرجات'!11:11))) -> 3 | E24: =IF(E$2="","",IF($C24="","",SUMIF('رصد الدرجات'!$3:$3,E$1,'رصد الدرجات'!11:11))) -> 41 | F24: =IF(F$2="","",IF($C24="","",SUMIF('رصد الدرجات'!$3:$3,F$1,'رصد الدرجات'!11:11))) -> 10 | G24: =IF(G$2="","",IF($C24="","",SUMIF('رصد الدرجات'!$3:$3,G$1,'رصد الدرجات'!11:11))) | H24: =IF(H$2="","",IF($C24="","",SUMIF('رصد الدرجات'!$3:$3,H$1,'رصد الدرجات'!11:11))) | I24: =IF(I$2="","",IF($C24="","",SUMIF('رصد الدرجات'!$3:$3,I$1,'رصد الدرجات'!11:11))) -> 2 | J24: =IF(J$2="","",IF($C24="","",SUMIF('رصد الدرجات'!$3:$3,J$1,'رصد الدرجات'!11:11))) -> 24 | K24: =IF(K$2="","",IF($C24="","",SUMIF('رصد الدرجات'!$3:$3,K$1,'رصد الدرجات'!11:11))) -> 13 | ... P24: =IF(P$2="","",IF($C24="","",SUMIF('رصد الدرجات'!$3:$3,P$1,'رصد الدرجات'!11:11))) -> 0 | Q24: =IF($C24="","",SUM(D24:P24)) -> 93 | R24: =IF(C24="","",IF(Q24>100,"خطأ",IF(Q24>=95,"أ+",IF(Q24>=90,"أ",IF(Q24>=85,"ب+",IF(Q24>=80,"ب",IF(Q24>=75,"ج+",IF(Q24>=70,"ج",IF(Q24>=65,"د+",IF(Q24>=60,"د",IF(Q24>=0,"ه",""))))))))))) -> أ
A25: ='رصد الدرجات'!A12 -> 5 | B25: =IF('رصد الدرجات'!B12="","",'رصد الدرجات'!B12) | C25: =IF('رصد الدرجات'!C12="","",'رصد الدرجات'!C12) -> إبراهيم باه | D25: =IF(D$2="","",IF($C25="","",SUMIF('رصد الدرجات'!$3:$3,D$1,'رصد الدرجات'!12:12))) -> 2 | E25: =IF(E$2="","",IF($C25="","",SUMIF('رصد الدرجات'!$3:$3,E$1,'رصد الدرجات'!12:12))) -> 44 | F25: =IF(F$2="","",IF($C25="","",SUMIF('رصد الدرجات'!$3:$3,F$1,'رصد الدرجات'!12:12))) -> 9 | G25: =IF(G$2="","",IF($C25="","",SUMIF('رصد الدرجات'!$3:$3,G$1,'رصد الدرجات'!12:12))) | H25: =IF(H$2="","",IF($C25="","",SUMIF('رصد الدرجات'!$3:$3,H$1,'رصد الدرجات'!12:12))) | I25: =IF(I$2="","",IF($C25="","",SUMIF('رصد الدرجات'!$3:$3,I$1,'رصد الدرجات'!12:12))) -> 3 | J25: =IF(J$2="","",IF($C25="","",SUMIF('رصد الدرجات'!$3:$3,J$1,'رصد الدرجات'!12:12))) -> 24 | K25: =IF(K$2="","",IF($C25="","",SUMIF('رصد الدرجات'!$3:$3,K$1,'رصد الدرجات'!12:12))) -> 14 | ... P25: =IF(P$2="","",IF($C25="","",SUMIF('رصد الدرجات'!$3:$3,P$1,'رصد الدرجات'!12:12))) -> 0 | Q25: =IF($C25="","",SUM(D25:P25)) -> 96 | R25: =IF(C25="","",IF(Q25>100,"خطأ",IF(Q25>=95,"أ+",IF(Q25>=90,"أ",IF(Q25>=85,"ب+",IF(Q25>=80,"ب",IF(Q25>=75,"ج+",IF(Q25>=70,"ج",IF(Q25>=65,"د+",IF(Q25>=60,"د",IF(Q25>=0,"ه",""))))))))))) -> أ+
A26: ='رصد الدرجات'!A13 -> 6 | B26: =IF('رصد الدرجات'!B13="","",'رصد الدرجات'!B13) | C26: =IF('رصد الدرجات'!C13="","",'رصد الدرجات'!C13) -> عبداللطيف محمد أمين | D26: =IF(D$2="","",IF($C26="","",SUMIF('رصد الدرجات'!$3:$3,D$1,'رصد الدرجات'!13:13))) -> 1.5 | E26: =IF(E$2="","",IF($C26="","",SUMIF('رصد الدرجات'!$3:$3,E$1,'رصد الدرجات'!13:13))) -> 44.5 | F26: =IF(F$2="","",IF($C26="","",SUMIF('رصد الدرجات'!$3:$3,F$1,'رصد الدرجات'!13:13))) -> 10 | G26: =IF(G$2="","",IF($C26="","",SUMIF('رصد الدرجات'!$3:$3,G$1,'رصد الدرجات'!13:13))) | H26: =IF(H$2="","",IF($C26="","",SUMIF('رصد الدرجات'!$3:$3,H$1,'رصد الدرجات'!13:13))) | I26: =IF(I$2="","",IF($C26="","",SUMIF('رصد الدرجات'!$3:$3,I$1,'رصد الدرجات'!13:13))) -> 2 | J26: =IF(J$2="","",IF($C26="","",SUMIF('رصد الدرجات'!$3:$3,J$1,'رصد الدرجات'!13:13))) -> 23 | K26: =IF(K$2="","",IF($C26="","",SUMIF('رصد الدرجات'!$3:$3,K$1,'رصد الدرجات'!13:13))) -> 16 | ... P26: =IF(P$2="","",IF($C26="","",SUMIF('رصد الدرجات'!$3:$3,P$1,'رصد الدرجات'!13:13))) -> 0 | Q26: =IF($C26="","",SUM(D26:P26)) -> 97 | R26: =IF(C26="","",IF(Q26>100,"خطأ",IF(Q26>=95,"أ+",IF(Q26>=90,"أ",IF(Q26>=85,"ب+",IF(Q26>=80,"ب",IF(Q26>=75,"ج+",IF(Q26>=70,"ج",IF(Q26>=65,"د+",IF(Q26>=60,"د",IF(Q26>=0,"ه",""))))))))))) -> أ+
A27: ='رصد الدرجات'!A14 -> 7 | B27: =IF('رصد الدرجات'!B14="","",'رصد الدرجات'!B14) | C27: =IF('رصد الدرجات'!C14="","",'رصد الدرجات'!C14) -> خالد الحربي | D27: =IF(D$2="","",IF($C27="","",SUMIF('رصد الدرجات'!$3:$3,D$1,'رصد الدرجات'!14:14))) -> 2 | E27: =IF(E$2="","",IF($C27="","",SUMIF('رصد الدرجات'!$3:$3,E$1,'رصد الدرجات'!14:14))) -> 44 | F27: =IF(F$2="","",IF($C27="","",SUMIF('رصد الدرجات'!$3:$3,F$1,'رصد الدرجات'!14:14))) -> 10 | G27: =IF(G$2="","",IF($C27="","",SUMIF('رصد الدرجات'!$3:$3,G$1,'رصد الدرجات'!14:14))) | H27: =IF(H$2="","",IF($C27="","",SUMIF('رصد الدرجات'!$3:$3,H$1,'رصد الدرجات'!14:14))) | I27: =IF(I$2="","",IF($C27="","",SUMIF('رصد الدرجات'!$3:$3,I$1,'رصد الدرجات'!14:14))) -> 2 | J27: =IF(J$2="","",IF($C27="","",SUMIF('رصد الدرجات'!$3:$3,J$1,'رصد الدرجات'!14:14))) -> 24 | K27: =IF(K$2="","",IF($C27="","",SUMIF('رصد الدرجات'!$3:$3,K$1,'رصد الدرجات'!14:14))) -> 15 | ... P27: =IF(P$2="","",IF($C27="","",SUMIF('رصد الدرجات'!$3:$3,P$1,'رصد الدرجات'!14:14))) -> 0 | Q27: =IF($C27="","",SUM(D27:P27)) -> 97 | R27: =IF(C27="","",IF(Q27>100,"خطأ",IF(Q27>=95,"أ+",IF(Q27>=90,"أ",IF(Q27>=85,"ب+",IF(Q27>=80,"ب",IF(Q27>=75,"ج+",IF(Q27>=70,"ج",IF(Q27>=65,"د+",IF(Q27>=60,"د",IF(Q27>=0,"ه",""))))))))))) -> أ+
A28: ='رصد الدرجات'!A15 -> 8 | B28: =IF('رصد الدرجات'!B15="","",'رصد الدرجات'!B15) | C28: =IF('رصد الدرجات'!C15="","",'رصد الدرجات'!C15) -> عبد الحكيم عبد الرحمن | D28: =IF(D$2="","",IF($C28="","",SUMIF('رصد الدرجات'!$3:$3,D$1,'رصد الدرجات'!15:15))) -> 2.5 | E28: =IF(E$2="","",IF($C28="","",SUMIF('رصد الدرجات'!$3:$3,E$1,'رصد الدرجات'!15:15))) -> 43.5 | F28: =IF(F$2="","",IF($C28="","",SUMIF('رصد الدرجات'!$3:$3,F$1,'رصد الدرجات'!15:15))) -> 11 | G28: =IF(G$2="","",IF($C28="","",SUMIF('رصد الدرجات'!$3:$3,G$1,'رصد الدرجات'!15:15))) | H28: =IF(H$2="","",IF($C28="","",SUMIF('رصد الدرجات'!$3:$3,H$1,'رصد الدرجات'!15:15))) | I28: =IF(I$2="","",IF($C28="","",SUMIF('رصد الدرجات'!$3:$3,I$1,'رصد الدرجات'!15:15))) -> 2 | J28: =IF(J$2="","",IF($C28="","",SUMIF('رصد الدرجات'!$3:$3,J$1,'رصد الدرجات'!15:15))) -> 23.5 | K28: =IF(K$2="","",IF($C28="","",SUMIF('رصد الدرجات'!$3:$3,K$1,'رصد الدرجات'!15:15))) -> 15.5 | ... P28: =IF(P$2="","",IF($C28="","",SUMIF('رصد الدرجات'!$3:$3,P$1,'رصد الدرجات'!15:15))) -> 0 | Q28: =IF($C28="","",SUM(D28:P28)) -> 98 | R28: =IF(C28="","",IF(Q28>100,"خطأ",IF(Q28>=95,"أ+",IF(Q28>=90,"أ",IF(Q28>=85,"ب+",IF(Q28>=80,"ب",IF(Q28>=75,"ج+",IF(Q28>=70,"ج",IF(Q28>=65,"د+",IF(Q28>=60,"د",IF(Q28>=0,"ه",""))))))))))) -> أ+
A29: ='رصد الدرجات'!A16 -> 9 | B29: =IF('رصد الدرجات'!B16="","",'رصد الدرجات'!B16) | C29: =IF('رصد الدرجات'!C16="","",'رصد الدرجات'!C16) -> محمد محبوب حسين | D29: =IF(D$2="","",IF($C29="","",SUMIF('رصد الدرجات'!$3:$3,D$1,'رصد الدرجات'!16:16))) -> 3 | E29: =IF(E$2="","",IF($C29="","",SUMIF('رصد الدرجات'!$3:$3,E$1,'رصد الدرجات'!16:16))) -> 38 | F29: =IF(F$2="","",IF($C29="","",SUMIF('رصد الدرجات'!$3:$3,F$1,'رصد الدرجات'!16:16))) -> 10 | G29: =IF(G$2="","",IF($C29="","",SUMIF('رصد الدرجات'!$3:$3,G$1,'رصد الدرجات'!16:16))) | H29: =IF(H$2="","",IF($C29="","",SUMIF('رصد الدرجات'!$3:$3,H$1,'رصد الدرجات'!16:16))) | I29: =IF(I$2="","",IF($C29="","",SUMIF('رصد الدرجات'!$3:$3,I$1,'رصد الدرجات'!16:16))) -> 2 | J29: =IF(J$2="","",IF($C29="","",SUMIF('رصد الدرجات'!$3:$3,J$1,'رصد الدرجات'!16:16))) -> 24 | K29: =IF(K$2="","",IF($C29="","",SUMIF('رصد الدرجات'!$3:$3,K$1,'رصد الدرجات'!16:16))) -> 14 | ... P29: =IF(P$2="","",IF($C29="","",SUMIF('رصد الدرجات'!$3:$3,P$1,'رصد الدرجات'!16:16))) -> 0 | Q29: =IF($C29="","",SUM(D29:P29)) -> 91 | R29: =IF(C29="","",IF(Q29>100,"خطأ",IF(Q29>=95,"أ+",IF(Q29>=90,"أ",IF(Q29>=85,"ب+",IF(Q29>=80,"ب",IF(Q29>=75,"ج+",IF(Q29>=70,"ج",IF(Q29>=65,"د+",IF(Q29>=60,"د",IF(Q29>=0,"ه",""))))))))))) -> أ
A30: ='رصد الدرجات'!A17 -> 10 | B30: =IF('رصد الدرجات'!B17="","",'رصد الدرجات'!B17) | C30: =IF('رصد الدرجات'!C17="","",'رصد الدرجات'!C17) -> محمد ريزا الغفاري | D30: =IF(D$2="","",IF($C30="","",SUMIF('رصد الدرجات'!$3:$3,D$1,'رصد الدرجات'!17:17))) -> 2.5 | E30: =IF(E$2="","",IF($C30="","",SUMIF('رصد الدرجات'!$3:$3,E$1,'رصد الدرجات'!17:17))) -> 34 | F30: =IF(F$2="","",IF($C30="","",SUMIF('رصد الدرجات'!$3:$3,F$1,'رصد الدرجات'!17:17))) -> 9.5 | G30: =IF(G$2="","",IF($C30="","",SUMIF('رصد الدرجات'!$3:$3,G$1,'رصد الدرجات'!17:17))) | H30: =IF(H$2="","",IF($C30="","",SUMIF('رصد الدرجات'!$3:$3,H$1,'رصد الدرجات'!17:17))) | I30: =IF(I$2="","",IF($C30="","",SUMIF('رصد الدرجات'!$3:$3,I$1,'رصد الدرجات'!17:17))) -> 3 | J30: =IF(J$2="","",IF($C30="","",SUMIF('رصد الدرجات'!$3:$3,J$1,'رصد الدرجات'!17:17))) -> 23 | K30: =IF(K$2="","",IF($C30="","",SUMIF('رصد الدرجات'!$3:$3,K$1,'رصد الدرجات'!17:17))) -> 11 | ... P30: =IF(P$2="","",IF($C30="","",SUMIF('رصد الدرجات'!$3:$3,P$1,'رصد الدرجات'!17:17))) -> 0 | Q30: =IF($C30="","",SUM(D30:P30)) -> 83 | R30: =IF(C30="","",IF(Q30>100,"خطأ",IF(Q30>=95,"أ+",IF(Q30>=90,"أ",IF(Q30>=85,"ب+",IF(Q30>=80,"ب",IF(Q30>=75,"ج+",IF(Q30>=70,"ج",IF(Q30>=65,"د+",IF(Q30>=60,"د",IF(Q30>=0,"ه",""))))))))))) -> ب
A31: ='رصد الدرجات'!A18 -> 11 | B31: =IF('رصد الدرجات'!B18="","",'رصد الدرجات'!B18) | C31: =IF('رصد الدرجات'!C18="","",'رصد الدرجات'!C18) -> سليمان حنيف | D31: =IF(D$2="","",IF($C31="","",SUMIF('رصد الدرجات'!$3:$3,D$1,'رصد الدرجات'!18:18))) -> 2 | E31: =IF(E$2="","",IF($C31="","",SUMIF('رصد الدرجات'!$3:$3,E$1,'رصد الدرجات'!18:18))) -> 45 | F31: =IF(F$2="","",IF($C31="","",SUMIF('رصد الدرجات'!$3:$3,F$1,'رصد الدرجات'!18:18))) -> 10 | G31: =IF(G$2="","",IF($C31="","",SUMIF('رصد الدرجات'!$3:$3,G$1,'رصد الدرجات'!18:18))) | H31: =IF(H$2="","",IF($C31="","",SUMIF('رصد الدرجات'!$3:$3,H$1,'رصد الدرجات'!18:18))) | I31: =IF(I$2="","",IF($C31="","",SUMIF('رصد الدرجات'!$3:$3,I$1,'رصد الدرجات'!18:18))) -> 2 | J31: =IF(J$2="","",IF($C31="","",SUMIF('رصد الدرجات'!$3:$3,J$1,'رصد الدرجات'!18:18))) -> 23 | K31: =IF(K$2="","",IF($C31="","",SUMIF('رصد الدرجات'!$3:$3,K$1,'رصد الدرجات'!18:18))) -> 16 | ... P31: =IF(P$2="","",IF($C31="","",SUMIF('رصد الدرجات'!$3:$3,P$1,'رصد الدرجات'!18:18))) -> 0 | Q31: =IF($C31="","",SUM(D31:P31)) -> 98 | R31: =IF(C31="","",IF(Q31>100,"خطأ",IF(Q31>=95,"أ+",IF(Q31>=90,"أ",IF(Q31>=85,"ب+",IF(Q31>=80,"ب",IF(Q31>=75,"ج+",IF(Q31>=70,"ج",IF(Q31>=65,"د+",IF(Q31>=60,"د",IF(Q31>=0,"ه",""))))))))))) -> أ+
A32: ='رصد الدرجات'!A19 -> 12 | B32: =IF('رصد الدرجات'!B19="","",'رصد الدرجات'!B19) | C32: =IF('رصد الدرجات'!C19="","",'رصد الدرجات'!C19) -> النفيدي محمد عثمان | D32: =IF(D$2="","",IF($C32="","",SUMIF('رصد الدرجات'!$3:$3,D$1,'رصد الدرجات'!19:19))) -> 2 | E32: =IF(E$2="","",IF($C32="","",SUMIF('رصد الدرجات'!$3:$3,E$1,'رصد الدرجات'!19:19))) -> 35 | F32: =IF(F$2="","",IF($C32="","",SUMIF('رصد الدرجات'!$3:$3,F$1,'رصد الدرجات'!19:19))) -> 8 | G32: =IF(G$2="","",IF($C32="","",SUMIF('رصد الدرجات'!$3:$3,G$1,'رصد الدرجات'!19:19))) | H32: =IF(H$2="","",IF($C32="","",SUMIF('رصد الدرجات'!$3:$3,H$1,'رصد الدرجات'!19:19))) | I32: =IF(I$2="","",IF($C32="","",SUMIF('رصد الدرجات'!$3:$3,I$1,'رصد الدرجات'!19:19))) -> 2 | J32: =IF(J$2="","",IF($C32="","",SUMIF('رصد الدرجات'!$3:$3,J$1,'رصد الدرجات'!19:19))) -> 17 | K32: =IF(K$2="","",IF($C32="","",SUMIF('رصد الدرجات'!$3:$3,K$1,'رصد الدرجات'!19:19))) -> 16 | ... P32: =IF(P$2="","",IF($C32="","",SUMIF('رصد الدرجات'!$3:$3,P$1,'رصد الدرجات'!19:19))) -> 0 | Q32: =IF($C32="","",SUM(D32:P32)) -> 80 | R32: =IF(C32="","",IF(Q32>100,"خطأ",IF(Q32>=95,"أ+",IF(Q32>=90,"أ",IF(Q32>=85,"ب+",IF(Q32>=80,"ب",IF(Q32>=75,"ج+",IF(Q32>=70,"ج",IF(Q32>=65,"د+",IF(Q32>=60,"د",IF(Q32>=0,"ه",""))))))))))) -> ب
A33: ='رصد الدرجات'!A20 -> 13 | B33: =IF('رصد الدرجات'!B20="","",'رصد الدرجات'!B20) | C33: =IF('رصد الدرجات'!C20="","",'رصد الدرجات'!C20) -> زبير عبدالسميع | D33: =IF(D$2="","",IF($C33="","",SUMIF('رصد الدرجات'!$3:$3,D$1,'رصد الدرجات'!20:20))) -> 0 | E33: =IF(E$2="","",IF($C33="","",SUMIF('رصد الدرجات'!$3:$3,E$1,'رصد الدرجات'!20:20))) -> 0 | F33: =IF(F$2="","",IF($C33="","",SUMIF('رصد الدرجات'!$3:$3,F$1,'رصد الدرجات'!20:20))) -> 0 | G33: =IF(G$2="","",IF($C33="","",SUMIF('رصد الدرجات'!$3:$3,G$1,'رصد الدرجات'!20:20))) | H33: =IF(H$2="","",IF($C33="","",SUMIF('رصد الدرجات'!$3:$3,H$1,'رصد الدرجات'!20:20))) | I33: =IF(I$2="","",IF($C33="","",SUMIF('رصد الدرجات'!$3:$3,I$1,'رصد الدرجات'!20:20))) -> 0 | J33: =IF(J$2="","",IF($C33="","",SUMIF('رصد الدرجات'!$3:$3,J$1,'رصد الدرجات'!20:20))) -> 0 | K33: =IF(K$2="","",IF($C33="","",SUMIF('رصد الدرجات'!$3:$3,K$1,'رصد الدرجات'!20:20))) -> 0 | ... P33: =IF(P$2="","",IF($C33="","",SUMIF('رصد الدرجات'!$3:$3,P$1,'رصد الدرجات'!20:20))) -> 0 | Q33: =IF($C33="","",SUM(D33:P33)) -> 0 | R33: =IF(C33="","",IF(Q33>100,"خطأ",IF(Q33>=95,"أ+",IF(Q33>=90,"أ",IF(Q33>=85,"ب+",IF(Q33>=80,"ب",IF(Q33>=75,"ج+",IF(Q33>=70,"ج",IF(Q33>=65,"د+",IF(Q33>=60,"د",IF(Q33>=0,"ه",""))))))))))) -> ه
A34: ='رصد الدرجات'!A21 -> 14 | B34: =IF('رصد الدرجات'!B21="","",'رصد الدرجات'!B21) | C34: =IF('رصد الدرجات'!C21="","",'رصد الدرجات'!C21) -> سهيل محمد مجددي | D34: =IF(D$2="","",IF($C34="","",SUMIF('رصد الدرجات'!$3:$3,D$1,'رصد الدرجات'!21:21))) -> 0 | E34: =IF(E$2="","",IF($C34="","",SUMIF('رصد الدرجات'!$3:$3,E$1,'رصد الدرجات'!21:21))) -> 0 | F34: =IF(F$2="","",IF($C34="","",SUMIF('رصد الدرجات'!$3:$3,F$1,'رصد الدرجات'!21:21))) -> 0 | G34: =IF(G$2="","",IF($C34="","",SUMIF('رصد الدرجات'!$3:$3,G$1,'رصد الدرجات'!21:21))) | H34: =IF(H$2="","",IF($C34="","",SUMIF('رصد الدرجات'!$3:$3,H$1,'رصد الدرجات'!21:21))) | I34: =IF(I$2="","",IF($C34="","",SUMIF('رصد الدرجات'!$3:$3,I$1,'رصد الدرجات'!21:21))) -> 0 | J34: =IF(J$2="","",IF($C34="","",SUMIF('رصد الدرجات'!$3:$3,J$1,'رصد الدرجات'!21:21))) -> 0 | K34: =IF(K$2="","",IF($C34="","",SUMIF('رصد الدرجات'!$3:$3,K$1,'رصد الدرجات'!21:21))) -> 0 | ... P34: =IF(P$2="","",IF($C34="","",SUMIF('رصد الدرجات'!$3:$3,P$1,'رصد الدرجات'!21:21))) -> 0 | Q34: =IF($C34="","",SUM(D34:P34)) -> 0 | R34: =IF(C34="","",IF(Q34>100,"خطأ",IF(Q34>=95,"أ+",IF(Q34>=90,"أ",IF(Q34>=85,"ب+",IF(Q34>=80,"ب",IF(Q34>=75,"ج+",IF(Q34>=70,"ج",IF(Q34>=65,"د+",IF(Q34>=60,"د",IF(Q34>=0,"ه",""))))))))))) -> ه
A35: ='رصد الدرجات'!A22 -> 15 | B35: =IF('رصد الدرجات'!B22="","",'رصد الدرجات'!B22) | C35: =IF('رصد الدرجات'!C22="","",'رصد الدرجات'!C22) -> أحمد رادباده | D35: =IF(D$2="","",IF($C35="","",SUMIF('رصد الدرجات'!$3:$3,D$1,'رصد الدرجات'!22:22))) -> 0 | E35: =IF(E$2="","",IF($C35="","",SUMIF('رصد الدرجات'!$3:$3,E$1,'رصد الدرجات'!22:22))) -> 0 | F35: =IF(F$2="","",IF($C35="","",SUMIF('رصد الدرجات'!$3:$3,F$1,'رصد الدرجات'!22:22))) -> 0 | G35: =IF(G$2="","",IF($C35="","",SUMIF('رصد الدرجات'!$3:$3,G$1,'رصد الدرجات'!22:22))) | H35: =IF(H$2="","",IF($C35="","",SUMIF('رصد الدرجات'!$3:$3,H$1,'رصد الدرجات'!22:22))) | I35: =IF(I$2="","",IF($C35="","",SUMIF('رصد الدرجات'!$3:$3,I$1,'رصد الدرجات'!22:22))) -> 0 | J35: =IF(J$2="","",IF($C35="","",SUMIF('رصد الدرجات'!$3:$3,J$1,'رصد الدرجات'!22:22))) -> 0 | K35: =IF(K$2="","",IF($C35="","",SUMIF('رصد الدرجات'!$3:$3,K$1,'رصد الدرجات'!22:22))) -> 0 | ... P35: =IF(P$2="","",IF($C35="","",SUMIF('رصد الدرجات'!$3:$3,P$1,'رصد الدرجات'!22:22))) -> 0 | Q35: =IF($C35="","",SUM(D35:P35)) -> 0 | R35: =IF(C35="","",IF(Q35>100,"خطأ",IF(Q35>=95,"أ+",IF(Q35>=90,"أ",IF(Q35>=85,"ب+",IF(Q35>=80,"ب",IF(Q35>=75,"ج+",IF(Q35>=70,"ج",IF(Q35>=65,"د+",IF(Q35>=60,"د",IF(Q35>=0,"ه",""))))))))))) -> ه
A36: ='رصد الدرجات'!A23 -> 16 | B36: =IF('رصد الدرجات'!B23="","",'رصد الدرجات'!B23) | C36: =IF('رصد الدرجات'!C23="","",'رصد الدرجات'!C23) -> محمد شفان | D36: =IF(D$2="","",IF($C36="","",SUMIF('رصد الدرجات'!$3:$3,D$1,'رصد الدرجات'!23:23))) -> 0 | E36: =IF(E$2="","",IF($C36="","",SUMIF('رصد الدرجات'!$3:$3,E$1,'رصد الدرجات'!23:23))) -> 0 | F36: =IF(F$2="","",IF($C36="","",SUMIF('رصد الدرجات'!$3:$3,F$1,'رصد الدرجات'!23:23))) -> 0 | G36: =IF(G$2="","",IF($C36="","",SUMIF('رصد الدرجات'!$3:$3,G$1,'رصد الدرجات'!23:23))) | H36: =IF(H$2="","",IF($C36="","",SUMIF('رصد الدرجات'!$3:$3,H$1,'رصد الدرجات'!23:23))) | I36: =IF(I$2="","",IF($C36="","",SUMIF('رصد الدرجات'!$3:$3,I$1,'رصد الدرجات'!23:23))) -> 0 | J36: =IF(J$2="","",IF($C36="","",SUMIF('رصد الدرجات'!$3:$3,J$1,'رصد الدرجات'!23:23))) -> 0 | K36: =IF(K$2="","",IF($C36="","",SUMIF('رصد الدرجات'!$3:$3,K$1,'رصد الدرجات'!23:23))) -> 0 | ... P36: =IF(P$2="","",IF($C36="","",SUMIF('رصد الدرجات'!$3:$3,P$1,'رصد الدرجات'!23:23))) -> 0 | Q36: =IF($C36="","",SUM(D36:P36)) -> 0 | R36: =IF(C36="","",IF(Q36>100,"خطأ",IF(Q36>=95,"أ+",IF(Q36>=90,"أ",IF(Q36>=85,"ب+",IF(Q36>=80,"ب",IF(Q36>=75,"ج+",IF(Q36>=70,"ج",IF(Q36>=65,"د+",IF(Q36>=60,"د",IF(Q36>=0,"ه",""))))))))))) -> ه
A37: ='رصد الدرجات'!A24 -> 17 | B37: =IF('رصد الدرجات'!B24="","",'رصد الدرجات'!B24) | C37: =IF('رصد الدرجات'!C24="","",'رصد الدرجات'!C24) -> سالم الهاجري | D37: =IF(D$2="","",IF($C37="","",SUMIF('رصد الدرجات'!$3:$3,D$1,'رصد الدرجات'!24:24))) -> 0 | E37: =IF(E$2="","",IF($C37="","",SUMIF('رصد الدرجات'!$3:$3,E$1,'رصد الدرجات'!24:24))) -> 0 | F37: =IF(F$2="","",IF($C37="","",SUMIF('رصد الدرجات'!$3:$3,F$1,'رصد الدرجات'!24:24))) -> 0 | G37: =IF(G$2="","",IF($C37="","",SUMIF('رصد الدرجات'!$3:$3,G$1,'رصد الدرجات'!24:24))) | H37: =IF(H$2="","",IF($C37="","",SUMIF('رصد الدرجات'!$3:$3,H$1,'رصد الدرجات'!24:24))) | I37: =IF(I$2="","",IF($C37="","",SUMIF('رصد الدرجات'!$3:$3,I$1,'رصد الدرجات'!24:24))) -> 0 | J37: =IF(J$2="","",IF($C37="","",SUMIF('رصد الدرجات'!$3:$3,J$1,'رصد الدرجات'!24:24))) -> 0 | K37: =IF(K$2="","",IF($C37="","",SUMIF('رصد الدرجات'!$3:$3,K$1,'رصد الدرجات'!24:24))) -> 0 | ... P37: =IF(P$2="","",IF($C37="","",SUMIF('رصد الدرجات'!$3:$3,P$1,'رصد الدرجات'!24:24))) -> 0 | Q37: =IF($C37="","",SUM(D37:P37)) -> 0 | R37: =IF(C37="","",IF(Q37>100,"خطأ",IF(Q37>=95,"أ+",IF(Q37>=90,"أ",IF(Q37>=85,"ب+",IF(Q37>=80,"ب",IF(Q37>=75,"ج+",IF(Q37>=70,"ج",IF(Q37>=65,"د+",IF(Q37>=60,"د",IF(Q37>=0,"ه",""))))))))))) -> ه
A38: ='رصد الدرجات'!A25 -> 18 | B38: =IF('رصد الدرجات'!B25="","",'رصد الدرجات'!B25) | C38: =IF('رصد الدرجات'!C25="","",'رصد الدرجات'!C25) -> سلمان المطيري | D38: =IF(D$2="","",IF($C38="","",SUMIF('رصد الدرجات'!$3:$3,D$1,'رصد الدرجات'!25:25))) -> 0 | E38: =IF(E$2="","",IF($C38="","",SUMIF('رصد الدرجات'!$3:$3,E$1,'رصد الدرجات'!25:25))) -> 0 | F38: =IF(F$2="","",IF($C38="","",SUMIF('رصد الدرجات'!$3:$3,F$1,'رصد الدرجات'!25:25))) -> 0 | G38: =IF(G$2="","",IF($C38="","",SUMIF('رصد الدرجات'!$3:$3,G$1,'رصد الدرجات'!25:25))) | H38: =IF(H$2="","",IF($C38="","",SUMIF('رصد الدرجات'!$3:$3,H$1,'رصد الدرجات'!25:25))) | I38: =IF(I$2="","",IF($C38="","",SUMIF('رصد الدرجات'!$3:$3,I$1,'رصد الدرجات'!25:25))) -> 0 | J38: =IF(J$2="","",IF($C38="","",SUMIF('رصد الدرجات'!$3:$3,J$1,'رصد الدرجات'!25:25))) -> 0 | K38: =IF(K$2="","",IF($C38="","",SUMIF('رصد الدرجات'!$3:$3,K$1,'رصد الدرجات'!25:25))) -> 0 | ... P38: =IF(P$2="","",IF($C38="","",SUMIF('رصد الدرجات'!$3:$3,P$1,'رصد الدرجات'!25:25))) -> 0 | Q38: =IF($C38="","",SUM(D38:P38)) -> 0 | R38: =IF(C38="","",IF(Q38>100,"خطأ",IF(Q38>=95,"أ+",IF(Q38>=90,"أ",IF(Q38>=85,"ب+",IF(Q38>=80,"ب",IF(Q38>=75,"ج+",IF(Q38>=70,"ج",IF(Q38>=65,"د+",IF(Q38>=60,"د",IF(Q38>=0,"ه",""))))))))))) -> ه
A39: ='رصد الدرجات'!A26 -> 19 | B39: =IF('رصد الدرجات'!B26="","",'رصد الدرجات'!B26) | C39: =IF('رصد الدرجات'!C26="","",'رصد الدرجات'!C26) -> علي الشنقيطي | D39: =IF(D$2="","",IF($C39="","",SUMIF('رصد الدرجات'!$3:$3,D$1,'رصد الدرجات'!26:26))) -> 0 | E39: =IF(E$2="","",IF($C39="","",SUMIF('رصد الدرجات'!$3:$3,E$1,'رصد الدرجات'!26:26))) -> 0 | F39: =IF(F$2="","",IF($C39="","",SUMIF('رصد الدرجات'!$3:$3,F$1,'رصد الدرجات'!26:26))) -> 0 | G39: =IF(G$2="","",IF($C39="","",SUMIF('رصد الدرجات'!$3:$3,G$1,'رصد الدرجات'!26:26))) | H39: =IF(H$2="","",IF($C39="","",SUMIF('رصد الدرجات'!$3:$3,H$1,'رصد الدرجات'!26:26))) | I39: =IF(I$2="","",IF($C39="","",SUMIF('رصد الدرجات'!$3:$3,I$1,'رصد الدرجات'!26:26))) -> 0 | J39: =IF(J$2="","",IF($C39="","",SUMIF('رصد الدرجات'!$3:$3,J$1,'رصد الدرجات'!26:26))) -> 0 | K39: =IF(K$2="","",IF($C39="","",SUMIF('رصد الدرجات'!$3:$3,K$1,'رصد الدرجات'!26:26))) -> 0 | ... P39: =IF(P$2="","",IF($C39="","",SUMIF('رصد الدرجات'!$3:$3,P$1,'رصد الدرجات'!26:26))) -> 0 | Q39: =IF($C39="","",SUM(D39:P39)) -> 0 | R39: =IF(C39="","",IF(Q39>100,"خطأ",IF(Q39>=95,"أ+",IF(Q39>=90,"أ",IF(Q39>=85,"ب+",IF(Q39>=80,"ب",IF(Q39>=75,"ج+",IF(Q39>=70,"ج",IF(Q39>=65,"د+",IF(Q39>=60,"د",IF(Q39>=0,"ه",""))))))))))) -> ه
A40: ='رصد الدرجات'!A27 -> 20 | B40: =IF('رصد الدرجات'!B27="","",'رصد الدرجات'!B27) | C40: =IF('رصد الدرجات'!C27="","",'رصد الدرجات'!C27) -> مسعود الرحمن | D40: =IF(D$2="","",IF($C40="","",SUMIF('رصد الدرجات'!$3:$3,D$1,'رصد الدرجات'!27:27))) -> 0 | E40: =IF(E$2="","",IF($C40="","",SUMIF('رصد الدرجات'!$3:$3,E$1,'رصد الدرجات'!27:27))) -> 0 | F40: =IF(F$2="","",IF($C40="","",SUMIF('رصد الدرجات'!$3:$3,F$1,'رصد الدرجات'!27:27))) -> 0 | G40: =IF(G$2="","",IF($C40="","",SUMIF('رصد الدرجات'!$3:$3,G$1,'رصد الدرجات'!27:27))) | H40: =IF(H$2="","",IF($C40="","",SUMIF('رصد الدرجات'!$3:$3,H$1,'رصد الدرجات'!27:27))) | I40: =IF(I$2="","",IF($C40="","",SUMIF('رصد الدرجات'!$3:$3,I$1,'رصد الدرجات'!27:27))) -> 0 | J40: =IF(J$2="","",IF($C40="","",SUMIF('رصد الدرجات'!$3:$3,J$1,'رصد الدرجات'!27:27))) -> 0 | K40: =IF(K$2="","",IF($C40="","",SUMIF('رصد الدرجات'!$3:$3,K$1,'رصد الدرجات'!27:27))) -> 0 | ... P40: =IF(P$2="","",IF($C40="","",SUMIF('رصد الدرجات'!$3:$3,P$1,'رصد الدرجات'!27:27))) -> 0 | Q40: =IF($C40="","",SUM(D40:P40)) -> 0 | R40: =IF(C40="","",IF(Q40>100,"خطأ",IF(Q40>=95,"أ+",IF(Q40>=90,"أ",IF(Q40>=85,"ب+",IF(Q40>=80,"ب",IF(Q40>=75,"ج+",IF(Q40>=70,"ج",IF(Q40>=65,"د+",IF(Q40>=60,"د",IF(Q40>=0,"ه",""))))))))))) -> ه
A41: ='رصد الدرجات'!A28 -> 21 | B41: =IF('رصد الدرجات'!B28="","",'رصد الدرجات'!B28) | C41: =IF('رصد الدرجات'!C28="","",'رصد الدرجات'!C28) -> مدثر محمد | D41: =IF(D$2="","",IF($C41="","",SUMIF('رصد الدرجات'!$3:$3,D$1,'رصد الدرجات'!28:28))) -> 0 | E41: =IF(E$2="","",IF($C41="","",SUMIF('رصد الدرجات'!$3:$3,E$1,'رصد الدرجات'!28:28))) -> 0 | F41: =IF(F$2="","",IF($C41="","",SUMIF('رصد الدرجات'!$3:$3,F$1,'رصد الدرجات'!28:28))) -> 0 | G41: =IF(G$2="","",IF($C41="","",SUMIF('رصد الدرجات'!$3:$3,G$1,'رصد الدرجات'!28:28))) | H41: =IF(H$2="","",IF($C41="","",SUMIF('رصد الدرجات'!$3:$3,H$1,'رصد الدرجات'!28:28))) | I41: =IF(I$2="","",IF($C41="","",SUMIF('رصد الدرجات'!$3:$3,I$1,'رصد الدرجات'!28:28))) -> 0 | J41: =IF(J$2="","",IF($C41="","",SUMIF('رصد الدرجات'!$3:$3,J$1,'رصد الدرجات'!28:28))) -> 0 | K41: =IF(K$2="","",IF($C41="","",SUMIF('رصد الدرجات'!$3:$3,K$1,'رصد الدرجات'!28:28))) -> 0 | ... P41: =IF(P$2="","",IF($C41="","",SUMIF('رصد الدرجات'!$3:$3,P$1,'رصد الدرجات'!28:28))) -> 0 | Q41: =IF($C41="","",SUM(D41:P41)) -> 0 | R41: =IF(C41="","",IF(Q41>100,"خطأ",IF(Q41>=95,"أ+",IF(Q41>=90,"أ",IF(Q41>=85,"ب+",IF(Q41>=80,"ب",IF(Q41>=75,"ج+",IF(Q41>=70,"ج",IF(Q41>=65,"د+",IF(Q41>=60,"د",IF(Q41>=0,"ه",""))))))))))) -> ه
A42: ='رصد الدرجات'!A29 -> 22 | B42: =IF('رصد الدرجات'!B29="","",'رصد الدرجات'!B29) | C42: =IF('رصد الدرجات'!C29="","",'رصد الدرجات'!C29) -> أبوبكر الماحي | D42: =IF(D$2="","",IF($C42="","",SUMIF('رصد الدرجات'!$3:$3,D$1,'رصد الدرجات'!29:29))) -> 0 | E42: =IF(E$2="","",IF($C42="","",SUMIF('رصد الدرجات'!$3:$3,E$1,'رصد الدرجات'!29:29))) -> 0 | F42: =IF(F$2="","",IF($C42="","",SUMIF('رصد الدرجات'!$3:$3,F$1,'رصد الدرجات'!29:29))) -> 0 | G42: =IF(G$2="","",IF($C42="","",SUMIF('رصد الدرجات'!$3:$3,G$1,'رصد الدرجات'!29:29))) | H42: =IF(H$2="","",IF($C42="","",SUMIF('رصد الدرجات'!$3:$3,H$1,'رصد الدرجات'!29:29))) | I42: =IF(I$2="","",IF($C42="","",SUMIF('رصد الدرجات'!$3:$3,I$1,'رصد الدرجات'!29:29))) -> 0 | J42: =IF(J$2="","",IF($C42="","",SUMIF('رصد الدرجات'!$3:$3,J$1,'رصد الدرجات'!29:29))) -> 0 | K42: =IF(K$2="","",IF($C42="","",SUMIF('رصد الدرجات'!$3:$3,K$1,'رصد الدرجات'!29:29))) -> 0 | ... P42: =IF(P$2="","",IF($C42="","",SUMIF('رصد الدرجات'!$3:$3,P$1,'رصد الدرجات'!29:29))) -> 0 | Q42: =IF($C42="","",SUM(D42:P42)) -> 0 | R42: =IF(C42="","",IF(Q42>100,"خطأ",IF(Q42>=95,"أ+",IF(Q42>=90,"أ",IF(Q42>=85,"ب+",IF(Q42>=80,"ب",IF(Q42>=75,"ج+",IF(Q42>=70,"ج",IF(Q42>=65,"د+",IF(Q42>=60,"د",IF(Q42>=0,"ه",""))))))))))) -> ه
A43: ='رصد الدرجات'!A30 -> 23 | B43: =IF('رصد الدرجات'!B30="","",'رصد الدرجات'!B30) | C43: =IF('رصد الدرجات'!C30="","",'رصد الدرجات'!C30) -> أبوكر عبدالمجيد | D43: =IF(D$2="","",IF($C43="","",SUMIF('رصد الدرجات'!$3:$3,D$1,'رصد الدرجات'!30:30))) -> 0 | E43: =IF(E$2="","",IF($C43="","",SUMIF('رصد الدرجات'!$3:$3,E$1,'رصد الدرجات'!30:30))) -> 0 | F43: =IF(F$2="","",IF($C43="","",SUMIF('رصد الدرجات'!$3:$3,F$1,'رصد الدرجات'!30:30))) -> 0 | G43: =IF(G$2="","",IF($C43="","",SUMIF('رصد الدرجات'!$3:$3,G$1,'رصد الدرجات'!30:30))) | H43: =IF(H$2="","",IF($C43="","",SUMIF('رصد الدرجات'!$3:$3,H$1,'رصد الدرجات'!30:30))) | I43: =IF(I$2="","",IF($C43="","",SUMIF('رصد الدرجات'!$3:$3,I$1,'رصد الدرجات'!30:30))) -> 0 | J43: =IF(J$2="","",IF($C43="","",SUMIF('رصد الدرجات'!$3:$3,J$1,'رصد الدرجات'!30:30))) -> 0 | K43: =IF(K$2="","",IF($C43="","",SUMIF('رصد الدرجات'!$3:$3,K$1,'رصد الدرجات'!30:30))) -> 0 | ... P43: =IF(P$2="","",IF($C43="","",SUMIF('رصد الدرجات'!$3:$3,P$1,'رصد الدرجات'!30:30))) -> 0 | Q43: =IF($C43="","",SUM(D43:P43)) -> 0 | R43: =IF(C43="","",IF(Q43>100,"خطأ",IF(Q43>=95,"أ+",IF(Q43>=90,"أ",IF(Q43>=85,"ب+",IF(Q43>=80,"ب",IF(Q43>=75,"ج+",IF(Q43>=70,"ج",IF(Q43>=65,"د+",IF(Q43>=60,"د",IF(Q43>=0,"ه",""))))))))))) -> ه
...
